Traceback (most recent call last):
  File "/home/runner/micromamba/envs/bids23/lib/python3.11/site-packages/jupyter_cache/executors/utils.py", line 58, in single_nb_execution
    executenb(
  File "/home/runner/micromamba/envs/bids23/lib/python3.11/site-packages/nbclient/client.py", line 1305, in execute
    return NotebookClient(nb=nb, resources=resources, km=km, **kwargs).execute()
           ^^^^^^^^^^^^^^^^^^^^^^^^^^^^^^^^^^^^^^^^^^^^^^^^^^^^^^^^^^^^^^^^^^^^^
  File "/home/runner/micromamba/envs/bids23/lib/python3.11/site-packages/jupyter_core/utils/__init__.py", line 173, in wrapped
    return loop.run_until_complete(inner)
           ^^^^^^^^^^^^^^^^^^^^^^^^^^^^^^
  File "/home/runner/micromamba/envs/bids23/lib/python3.11/asyncio/base_events.py", line 653, in run_until_complete
    return future.result()
           ^^^^^^^^^^^^^^^
  File "/home/runner/micromamba/envs/bids23/lib/python3.11/site-packages/nbclient/client.py", line 705, in async_execute
    await self.async_execute_cell(
  File "/home/runner/micromamba/envs/bids23/lib/python3.11/site-packages/nbclient/client.py", line 1058, in async_execute_cell
    await self._check_raise_for_error(cell, cell_index, exec_reply)
  File "/home/runner/micromamba/envs/bids23/lib/python3.11/site-packages/nbclient/client.py", line 914, in _check_raise_for_error
    raise CellExecutionError.from_cell_and_msg(cell, exec_reply_content)
nbclient.exceptions.CellExecutionError: An error occurred while executing the following cell:
------------------
remote_filename = 'https://object-store.cloud.muni.cz/swift/v1/foss4g-data/CGLS_LTS_1999_2019/c_gls_NDVI-LTS_1999-2019-1221_GLOBE_VGT-PROBAV_V3.0.1.nc'
with fsspec.open(remote_filename) as inf:
    h5chunks = kerchunk.hdf.SingleHdf5ToZarr(inf, remote_filename, inline_threshold=100)
    chunk_info = h5chunks.translate()
------------------


[0;31m---------------------------------------------------------------------------[0m
[0;31mNameError[0m                                 Traceback (most recent call last)
Cell [0;32mIn[24], line 2[0m
[1;32m      1[0m remote_filename [38;5;241m=[39m [38;5;124m'[39m[38;5;124mhttps://object-store.cloud.muni.cz/swift/v1/foss4g-data/CGLS_LTS_1999_2019/c_gls_NDVI-LTS_1999-2019-1221_GLOBE_VGT-PROBAV_V3.0.1.nc[39m[38;5;124m'[39m
[0;32m----> 2[0m [38;5;28;01mwith[39;00m [43mfsspec[49m[38;5;241m.[39mopen(remote_filename) [38;5;28;01mas[39;00m inf:
[1;32m      3[0m     h5chunks [38;5;241m=[39m kerchunk[38;5;241m.[39mhdf[38;5;241m.[39mSingleHdf5ToZarr(inf, remote_filename, inline_threshold[38;5;241m=[39m[38;5;241m100[39m)
[1;32m      4[0m     chunk_info [38;5;241m=[39m h5chunks[38;5;241m.[39mtranslate()

[0;31mNameError[0m: name 'fsspec' is not defined

