Traceback (most recent call last):
  File "/home/runner/micromamba/envs/bids23/lib/python3.11/site-packages/jupyter_cache/executors/utils.py", line 58, in single_nb_execution
    executenb(
  File "/home/runner/micromamba/envs/bids23/lib/python3.11/site-packages/nbclient/client.py", line 1305, in execute
    return NotebookClient(nb=nb, resources=resources, km=km, **kwargs).execute()
           ^^^^^^^^^^^^^^^^^^^^^^^^^^^^^^^^^^^^^^^^^^^^^^^^^^^^^^^^^^^^^^^^^^^^^
  File "/home/runner/micromamba/envs/bids23/lib/python3.11/site-packages/jupyter_core/utils/__init__.py", line 165, in wrapped
    return loop.run_until_complete(inner)
           ^^^^^^^^^^^^^^^^^^^^^^^^^^^^^^
  File "/home/runner/micromamba/envs/bids23/lib/python3.11/asyncio/base_events.py", line 654, in run_until_complete
    return future.result()
           ^^^^^^^^^^^^^^^
  File "/home/runner/micromamba/envs/bids23/lib/python3.11/site-packages/nbclient/client.py", line 705, in async_execute
    await self.async_execute_cell(
  File "/home/runner/micromamba/envs/bids23/lib/python3.11/site-packages/nbclient/client.py", line 1058, in async_execute_cell
    await self._check_raise_for_error(cell, cell_index, exec_reply)
  File "/home/runner/micromamba/envs/bids23/lib/python3.11/site-packages/nbclient/client.py", line 914, in _check_raise_for_error
    raise CellExecutionError.from_cell_and_msg(cell, exec_reply_content)
nbclient.exceptions.CellExecutionError: An error occurred while executing the following cell:
------------------
# Connect to the Dask Gateway
from dask_gateway import Gateway
gateway = Gateway()

#List activated cluster

clusters = gateway.list_clusters()
print(clusters)

#Clean clusters running on your name before starting a new one
for cluster in clusters:
    cluster = gateway.connect(cluster.name)
    cluster.shutdown()

#Create a new cluster and scale it to four workers
cluster = gateway.new_cluster()
cluster.scale(4)
cluster
------------------


[0;31m---------------------------------------------------------------------------[0m
[0;31mModuleNotFoundError[0m                       Traceback (most recent call last)
Cell [0;32mIn[2], line 2[0m
[1;32m      1[0m [38;5;66;03m# Connect to the Dask Gateway[39;00m
[0;32m----> 2[0m [38;5;28;01mfrom[39;00m [38;5;21;01mdask_gateway[39;00m [38;5;28;01mimport[39;00m Gateway
[1;32m      3[0m gateway [38;5;241m=[39m Gateway()
[1;32m      5[0m [38;5;66;03m#List activated cluster[39;00m

[0;31mModuleNotFoundError[0m: No module named 'dask_gateway'

