Traceback (most recent call last):
  File "/home/runner/micromamba/envs/bids23/lib/python3.11/site-packages/jupyter_cache/executors/utils.py", line 58, in single_nb_execution
    executenb(
  File "/home/runner/micromamba/envs/bids23/lib/python3.11/site-packages/nbclient/client.py", line 1305, in execute
    return NotebookClient(nb=nb, resources=resources, km=km, **kwargs).execute()
           ^^^^^^^^^^^^^^^^^^^^^^^^^^^^^^^^^^^^^^^^^^^^^^^^^^^^^^^^^^^^^^^^^^^^^
  File "/home/runner/micromamba/envs/bids23/lib/python3.11/site-packages/jupyter_core/utils/__init__.py", line 173, in wrapped
    return loop.run_until_complete(inner)
           ^^^^^^^^^^^^^^^^^^^^^^^^^^^^^^
  File "/home/runner/micromamba/envs/bids23/lib/python3.11/asyncio/base_events.py", line 653, in run_until_complete
    return future.result()
           ^^^^^^^^^^^^^^^
  File "/home/runner/micromamba/envs/bids23/lib/python3.11/site-packages/nbclient/client.py", line 705, in async_execute
    await self.async_execute_cell(
  File "/home/runner/micromamba/envs/bids23/lib/python3.11/site-packages/nbclient/client.py", line 1058, in async_execute_cell
    await self._check_raise_for_error(cell, cell_index, exec_reply)
  File "/home/runner/micromamba/envs/bids23/lib/python3.11/site-packages/nbclient/client.py", line 914, in _check_raise_for_error
    raise CellExecutionError.from_cell_and_msg(cell, exec_reply_content)
nbclient.exceptions.CellExecutionError: An error occurred while executing the following cell:
------------------
from openeo.local import LocalConnection
local_conn = LocalConnection("./")
------------------


[0;31m---------------------------------------------------------------------------[0m
[0;31mModuleNotFoundError[0m                       Traceback (most recent call last)
Cell [0;32mIn[1], line 1[0m
[0;32m----> 1[0m [38;5;28;01mfrom[39;00m [38;5;21;01mopeneo[39;00m[38;5;21;01m.[39;00m[38;5;21;01mlocal[39;00m [38;5;28;01mimport[39;00m LocalConnection
[1;32m      2[0m local_conn [38;5;241m=[39m LocalConnection([38;5;124m"[39m[38;5;124m./[39m[38;5;124m"[39m)

File [0;32m~/micromamba/envs/bids23/lib/python3.11/site-packages/openeo/local/__init__.py:1[0m
[0;32m----> 1[0m [38;5;28;01mfrom[39;00m [38;5;21;01mopeneo[39;00m[38;5;21;01m.[39;00m[38;5;21;01mlocal[39;00m[38;5;21;01m.[39;00m[38;5;21;01mconnection[39;00m [38;5;28;01mimport[39;00m LocalConnection
[1;32m      3[0m __all__ [38;5;241m=[39m [[38;5;124m"[39m[38;5;124mLocalConnection[39m[38;5;124m"[39m]

File [0;32m~/micromamba/envs/bids23/lib/python3.11/site-packages/openeo/local/connection.py:8[0m
[1;32m      6[0m [38;5;28;01mimport[39;00m [38;5;21;01mnumpy[39;00m [38;5;28;01mas[39;00m [38;5;21;01mnp[39;00m
[1;32m      7[0m [38;5;28;01mimport[39;00m [38;5;21;01mxarray[39;00m [38;5;28;01mas[39;00m [38;5;21;01mxr[39;00m
[0;32m----> 8[0m [38;5;28;01mfrom[39;00m [38;5;21;01mopeneo_pg_parser_networkx[39;00m[38;5;21;01m.[39;00m[38;5;21;01mgraph[39;00m [38;5;28;01mimport[39;00m OpenEOProcessGraph
[1;32m      9[0m [38;5;28;01mfrom[39;00m [38;5;21;01mopeneo_pg_parser_networkx[39;00m[38;5;21;01m.[39;00m[38;5;21;01mpg_schema[39;00m [38;5;28;01mimport[39;00m BoundingBox, TemporalInterval
[1;32m     10[0m [38;5;28;01mfrom[39;00m [38;5;21;01mopeneo_processes_dask[39;00m[38;5;21;01m.[39;00m[38;5;21;01mprocess_implementations[39;00m[38;5;21;01m.[39;00m[38;5;21;01mcubes[39;00m [38;5;28;01mimport[39;00m load_stac

[0;31mModuleNotFoundError[0m: No module named 'openeo_pg_parser_networkx'

